telegram.ext.updater - ERROR - Error while getting Updates: Timed out
telegram.ext.dispatcher - ERROR - No error handlers are registered, logging exception...
Traceback (most recent call last):
  File "C:\Users\Kryukov_MM\AppData\Local\Programs\Python\Python37\lib\site-packages\telegram\vendor\ptb_urllib3\urllib3\connectionpool.py", line 402, in _make_request
    six.raise_from(e, None)
  File "<string>", line 2, in raise_from
  File "C:\Users\Kryukov_MM\AppData\Local\Programs\Python\Python37\lib\site-packages\telegram\vendor\ptb_urllib3\urllib3\connectionpool.py", line 398, in _make_request
    httplib_response = conn.getresponse()
  File "C:\Users\Kryukov_MM\AppData\Local\Programs\Python\Python37\lib\http\client.py", line 1321, in getresponse
    response.begin()
  File "C:\Users\Kryukov_MM\AppData\Local\Programs\Python\Python37\lib\http\client.py", line 296, in begin
    version, status, reason = self._read_status()
  File "C:\Users\Kryukov_MM\AppData\Local\Programs\Python\Python37\lib\http\client.py", line 257, in _read_status
    line = str(self.fp.readline(_MAXLINE + 1), "iso-8859-1")
  File "C:\Users\Kryukov_MM\AppData\Local\Programs\Python\Python37\lib\socket.py", line 589, in readinto
    return self._sock.recv_into(b)
  File "C:\Users\Kryukov_MM\AppData\Local\Programs\Python\Python37\lib\ssl.py", line 987, in recv_into
    return self.read(nbytes, buffer)
  File "C:\Users\Kryukov_MM\AppData\Local\Programs\Python\Python37\lib\ssl.py", line 849, in read
    return self._sslobj.read(len, buffer)
  File "C:\Users\Kryukov_MM\AppData\Local\Programs\Python\Python37\lib\ssl.py", line 615, in read
    v = self._sslobj.read(len, buffer)
socket.timeout: The read operation timed out

During handling of the above exception, another exception occurred:

Traceback (most recent call last):
  File "C:\Users\Kryukov_MM\AppData\Local\Programs\Python\Python37\lib\site-packages\telegram\utils\request.py", line 190, in _request_wrapper
    resp = self._con_pool.request(*args, **kwargs)
  File "C:\Users\Kryukov_MM\AppData\Local\Programs\Python\Python37\lib\site-packages\telegram\vendor\ptb_urllib3\urllib3\request.py", line 70, in request
    **urlopen_kw)
  File "C:\Users\Kryukov_MM\AppData\Local\Programs\Python\Python37\lib\site-packages\telegram\vendor\ptb_urllib3\urllib3\request.py", line 148, in request_encode_body
    return self.urlopen(method, url, **extra_kw)
  File "C:\Users\Kryukov_MM\AppData\Local\Programs\Python\Python37\lib\site-packages\telegram\vendor\ptb_urllib3\urllib3\poolmanager.py", line 244, in urlopen
    response = conn.urlopen(method, u.request_uri, **kw)
  File "C:\Users\Kryukov_MM\AppData\Local\Programs\Python\Python37\lib\site-packages\telegram\vendor\ptb_urllib3\urllib3\connectionpool.py", line 666, in urlopen
    _stacktrace=sys.exc_info()[2])
  File "C:\Users\Kryukov_MM\AppData\Local\Programs\Python\Python37\lib\site-packages\telegram\vendor\ptb_urllib3\urllib3\util\retry.py", line 347, in increment
    raise six.reraise(type(error), error, _stacktrace)
  File "C:\Users\Kryukov_MM\AppData\Local\Programs\Python\Python37\lib\site-packages\telegram\vendor\ptb_urllib3\urllib3\packages\six.py", line 686, in reraise
    raise value
  File "C:\Users\Kryukov_MM\AppData\Local\Programs\Python\Python37\lib\site-packages\telegram\vendor\ptb_urllib3\urllib3\connectionpool.py", line 617, in urlopen
    chunked=chunked)
  File "C:\Users\Kryukov_MM\AppData\Local\Programs\Python\Python37\lib\site-packages\telegram\vendor\ptb_urllib3\urllib3\connectionpool.py", line 405, in _make_request
    exc_cls=ReadTimeoutError)
  File "C:\Users\Kryukov_MM\AppData\Local\Programs\Python\Python37\lib\site-packages\telegram\vendor\ptb_urllib3\urllib3\connectionpool.py", line 321, in _raise_timeout
    raise exc_cls(*args)
telegram.vendor.ptb_urllib3.urllib3.exceptions.ReadTimeoutError: HTTPSConnectionPool(host='api.telegram.org', port=443): Read timed out. (read timeout=12.0)

During handling of the above exception, another exception occurred:

Traceback (most recent call last):
  File "C:\Users\Kryukov_MM\AppData\Local\Programs\Python\Python37\lib\site-packages\telegram\ext\updater.py", line 286, in _start_polling
    allowed_updates=allowed_updates)
  File "C:\Users\Kryukov_MM\AppData\Local\Programs\Python\Python37\lib\site-packages\telegram\bot.py", line 60, in decorator
    result = func(self, *args, **kwargs)
  File "C:\Users\Kryukov_MM\AppData\Local\Programs\Python\Python37\lib\site-packages\telegram\bot.py", line 1720, in get_updates
    result = self._request.post(url, data, timeout=float(read_latency) + float(timeout))
  File "C:\Users\Kryukov_MM\AppData\Local\Programs\Python\Python37\lib\site-packages\telegram\utils\request.py", line 272, in post
    **urlopen_kwargs)
  File "C:\Users\Kryukov_MM\AppData\Local\Programs\Python\Python37\lib\site-packages\telegram\utils\request.py", line 192, in _request_wrapper
    raise TimedOut()
telegram.error.TimedOut: Timed out
telegram.ext.updater - ERROR - Error while getting Updates: Timed out
telegram.ext.dispatcher - ERROR - No error handlers are registered, logging exception...
Traceback (most recent call last):
  File "C:\Users\Kryukov_MM\AppData\Local\Programs\Python\Python37\lib\site-packages\telegram\vendor\ptb_urllib3\urllib3\connectionpool.py", line 402, in _make_request
    six.raise_from(e, None)
  File "<string>", line 2, in raise_from
  File "C:\Users\Kryukov_MM\AppData\Local\Programs\Python\Python37\lib\site-packages\telegram\vendor\ptb_urllib3\urllib3\connectionpool.py", line 398, in _make_request
    httplib_response = conn.getresponse()
  File "C:\Users\Kryukov_MM\AppData\Local\Programs\Python\Python37\lib\http\client.py", line 1321, in getresponse
    response.begin()
  File "C:\Users\Kryukov_MM\AppData\Local\Programs\Python\Python37\lib\http\client.py", line 296, in begin
    version, status, reason = self._read_status()
  File "C:\Users\Kryukov_MM\AppData\Local\Programs\Python\Python37\lib\http\client.py", line 257, in _read_status
    line = str(self.fp.readline(_MAXLINE + 1), "iso-8859-1")
  File "C:\Users\Kryukov_MM\AppData\Local\Programs\Python\Python37\lib\socket.py", line 589, in readinto
    return self._sock.recv_into(b)
  File "C:\Users\Kryukov_MM\AppData\Local\Programs\Python\Python37\lib\ssl.py", line 987, in recv_into
    return self.read(nbytes, buffer)
  File "C:\Users\Kryukov_MM\AppData\Local\Programs\Python\Python37\lib\ssl.py", line 849, in read
    return self._sslobj.read(len, buffer)
  File "C:\Users\Kryukov_MM\AppData\Local\Programs\Python\Python37\lib\ssl.py", line 615, in read
    v = self._sslobj.read(len, buffer)
socket.timeout: The read operation timed out

During handling of the above exception, another exception occurred:

Traceback (most recent call last):
  File "C:\Users\Kryukov_MM\AppData\Local\Programs\Python\Python37\lib\site-packages\telegram\utils\request.py", line 190, in _request_wrapper
    resp = self._con_pool.request(*args, **kwargs)
  File "C:\Users\Kryukov_MM\AppData\Local\Programs\Python\Python37\lib\site-packages\telegram\vendor\ptb_urllib3\urllib3\request.py", line 70, in request
    **urlopen_kw)
  File "C:\Users\Kryukov_MM\AppData\Local\Programs\Python\Python37\lib\site-packages\telegram\vendor\ptb_urllib3\urllib3\request.py", line 148, in request_encode_body
    return self.urlopen(method, url, **extra_kw)
  File "C:\Users\Kryukov_MM\AppData\Local\Programs\Python\Python37\lib\site-packages\telegram\vendor\ptb_urllib3\urllib3\poolmanager.py", line 244, in urlopen
    response = conn.urlopen(method, u.request_uri, **kw)
  File "C:\Users\Kryukov_MM\AppData\Local\Programs\Python\Python37\lib\site-packages\telegram\vendor\ptb_urllib3\urllib3\connectionpool.py", line 666, in urlopen
    _stacktrace=sys.exc_info()[2])
  File "C:\Users\Kryukov_MM\AppData\Local\Programs\Python\Python37\lib\site-packages\telegram\vendor\ptb_urllib3\urllib3\util\retry.py", line 347, in increment
    raise six.reraise(type(error), error, _stacktrace)
  File "C:\Users\Kryukov_MM\AppData\Local\Programs\Python\Python37\lib\site-packages\telegram\vendor\ptb_urllib3\urllib3\packages\six.py", line 686, in reraise
    raise value
  File "C:\Users\Kryukov_MM\AppData\Local\Programs\Python\Python37\lib\site-packages\telegram\vendor\ptb_urllib3\urllib3\connectionpool.py", line 617, in urlopen
    chunked=chunked)
  File "C:\Users\Kryukov_MM\AppData\Local\Programs\Python\Python37\lib\site-packages\telegram\vendor\ptb_urllib3\urllib3\connectionpool.py", line 405, in _make_request
    exc_cls=ReadTimeoutError)
  File "C:\Users\Kryukov_MM\AppData\Local\Programs\Python\Python37\lib\site-packages\telegram\vendor\ptb_urllib3\urllib3\connectionpool.py", line 321, in _raise_timeout
    raise exc_cls(*args)
telegram.vendor.ptb_urllib3.urllib3.exceptions.ReadTimeoutError: HTTPSConnectionPool(host='api.telegram.org', port=443): Read timed out. (read timeout=12.0)

During handling of the above exception, another exception occurred:

Traceback (most recent call last):
  File "C:\Users\Kryukov_MM\AppData\Local\Programs\Python\Python37\lib\site-packages\telegram\ext\updater.py", line 286, in _start_polling
    allowed_updates=allowed_updates)
  File "C:\Users\Kryukov_MM\AppData\Local\Programs\Python\Python37\lib\site-packages\telegram\bot.py", line 60, in decorator
    result = func(self, *args, **kwargs)
  File "C:\Users\Kryukov_MM\AppData\Local\Programs\Python\Python37\lib\site-packages\telegram\bot.py", line 1720, in get_updates
    result = self._request.post(url, data, timeout=float(read_latency) + float(timeout))
  File "C:\Users\Kryukov_MM\AppData\Local\Programs\Python\Python37\lib\site-packages\telegram\utils\request.py", line 272, in post
    **urlopen_kwargs)
  File "C:\Users\Kryukov_MM\AppData\Local\Programs\Python\Python37\lib\site-packages\telegram\utils\request.py", line 192, in _request_wrapper
    raise TimedOut()
telegram.error.TimedOut: Timed out
telegram.ext.updater - ERROR - Error while getting Updates: Timed out
telegram.ext.dispatcher - ERROR - No error handlers are registered, logging exception...
Traceback (most recent call last):
  File "C:\Users\Kryukov_MM\AppData\Local\Programs\Python\Python37\lib\site-packages\telegram\vendor\ptb_urllib3\urllib3\connectionpool.py", line 402, in _make_request
    six.raise_from(e, None)
  File "<string>", line 2, in raise_from
  File "C:\Users\Kryukov_MM\AppData\Local\Programs\Python\Python37\lib\site-packages\telegram\vendor\ptb_urllib3\urllib3\connectionpool.py", line 398, in _make_request
    httplib_response = conn.getresponse()
  File "C:\Users\Kryukov_MM\AppData\Local\Programs\Python\Python37\lib\http\client.py", line 1321, in getresponse
    response.begin()
  File "C:\Users\Kryukov_MM\AppData\Local\Programs\Python\Python37\lib\http\client.py", line 296, in begin
    version, status, reason = self._read_status()
  File "C:\Users\Kryukov_MM\AppData\Local\Programs\Python\Python37\lib\http\client.py", line 257, in _read_status
    line = str(self.fp.readline(_MAXLINE + 1), "iso-8859-1")
  File "C:\Users\Kryukov_MM\AppData\Local\Programs\Python\Python37\lib\socket.py", line 589, in readinto
    return self._sock.recv_into(b)
  File "C:\Users\Kryukov_MM\AppData\Local\Programs\Python\Python37\lib\ssl.py", line 987, in recv_into
    return self.read(nbytes, buffer)
  File "C:\Users\Kryukov_MM\AppData\Local\Programs\Python\Python37\lib\ssl.py", line 849, in read
    return self._sslobj.read(len, buffer)
  File "C:\Users\Kryukov_MM\AppData\Local\Programs\Python\Python37\lib\ssl.py", line 615, in read
    v = self._sslobj.read(len, buffer)
socket.timeout: The read operation timed out

During handling of the above exception, another exception occurred:

Traceback (most recent call last):
  File "C:\Users\Kryukov_MM\AppData\Local\Programs\Python\Python37\lib\site-packages\telegram\utils\request.py", line 190, in _request_wrapper
    resp = self._con_pool.request(*args, **kwargs)
  File "C:\Users\Kryukov_MM\AppData\Local\Programs\Python\Python37\lib\site-packages\telegram\vendor\ptb_urllib3\urllib3\request.py", line 70, in request
    **urlopen_kw)
  File "C:\Users\Kryukov_MM\AppData\Local\Programs\Python\Python37\lib\site-packages\telegram\vendor\ptb_urllib3\urllib3\request.py", line 148, in request_encode_body
    return self.urlopen(method, url, **extra_kw)
  File "C:\Users\Kryukov_MM\AppData\Local\Programs\Python\Python37\lib\site-packages\telegram\vendor\ptb_urllib3\urllib3\poolmanager.py", line 244, in urlopen
    response = conn.urlopen(method, u.request_uri, **kw)
  File "C:\Users\Kryukov_MM\AppData\Local\Programs\Python\Python37\lib\site-packages\telegram\vendor\ptb_urllib3\urllib3\connectionpool.py", line 666, in urlopen
    _stacktrace=sys.exc_info()[2])
  File "C:\Users\Kryukov_MM\AppData\Local\Programs\Python\Python37\lib\site-packages\telegram\vendor\ptb_urllib3\urllib3\util\retry.py", line 347, in increment
    raise six.reraise(type(error), error, _stacktrace)
  File "C:\Users\Kryukov_MM\AppData\Local\Programs\Python\Python37\lib\site-packages\telegram\vendor\ptb_urllib3\urllib3\packages\six.py", line 686, in reraise
    raise value
  File "C:\Users\Kryukov_MM\AppData\Local\Programs\Python\Python37\lib\site-packages\telegram\vendor\ptb_urllib3\urllib3\connectionpool.py", line 617, in urlopen
    chunked=chunked)
  File "C:\Users\Kryukov_MM\AppData\Local\Programs\Python\Python37\lib\site-packages\telegram\vendor\ptb_urllib3\urllib3\connectionpool.py", line 405, in _make_request
    exc_cls=ReadTimeoutError)
  File "C:\Users\Kryukov_MM\AppData\Local\Programs\Python\Python37\lib\site-packages\telegram\vendor\ptb_urllib3\urllib3\connectionpool.py", line 321, in _raise_timeout
    raise exc_cls(*args)
telegram.vendor.ptb_urllib3.urllib3.exceptions.ReadTimeoutError: HTTPSConnectionPool(host='api.telegram.org', port=443): Read timed out. (read timeout=12.0)

During handling of the above exception, another exception occurred:

Traceback (most recent call last):
  File "C:\Users\Kryukov_MM\AppData\Local\Programs\Python\Python37\lib\site-packages\telegram\ext\updater.py", line 286, in _start_polling
    allowed_updates=allowed_updates)
  File "C:\Users\Kryukov_MM\AppData\Local\Programs\Python\Python37\lib\site-packages\telegram\bot.py", line 60, in decorator
    result = func(self, *args, **kwargs)
  File "C:\Users\Kryukov_MM\AppData\Local\Programs\Python\Python37\lib\site-packages\telegram\bot.py", line 1720, in get_updates
    result = self._request.post(url, data, timeout=float(read_latency) + float(timeout))
  File "C:\Users\Kryukov_MM\AppData\Local\Programs\Python\Python37\lib\site-packages\telegram\utils\request.py", line 272, in post
    **urlopen_kwargs)
  File "C:\Users\Kryukov_MM\AppData\Local\Programs\Python\Python37\lib\site-packages\telegram\utils\request.py", line 192, in _request_wrapper
    raise TimedOut()
telegram.error.TimedOut: Timed out
telegram.ext.updater - ERROR - Error while getting Updates: Timed out
telegram.ext.dispatcher - ERROR - No error handlers are registered, logging exception...
Traceback (most recent call last):
  File "C:\Users\Kryukov_MM\AppData\Local\Programs\Python\Python37\lib\site-packages\telegram\vendor\ptb_urllib3\urllib3\connectionpool.py", line 402, in _make_request
    six.raise_from(e, None)
  File "<string>", line 2, in raise_from
  File "C:\Users\Kryukov_MM\AppData\Local\Programs\Python\Python37\lib\site-packages\telegram\vendor\ptb_urllib3\urllib3\connectionpool.py", line 398, in _make_request
    httplib_response = conn.getresponse()
  File "C:\Users\Kryukov_MM\AppData\Local\Programs\Python\Python37\lib\http\client.py", line 1321, in getresponse
    response.begin()
  File "C:\Users\Kryukov_MM\AppData\Local\Programs\Python\Python37\lib\http\client.py", line 296, in begin
    version, status, reason = self._read_status()
  File "C:\Users\Kryukov_MM\AppData\Local\Programs\Python\Python37\lib\http\client.py", line 257, in _read_status
    line = str(self.fp.readline(_MAXLINE + 1), "iso-8859-1")
  File "C:\Users\Kryukov_MM\AppData\Local\Programs\Python\Python37\lib\socket.py", line 589, in readinto
    return self._sock.recv_into(b)
  File "C:\Users\Kryukov_MM\AppData\Local\Programs\Python\Python37\lib\ssl.py", line 987, in recv_into
    return self.read(nbytes, buffer)
  File "C:\Users\Kryukov_MM\AppData\Local\Programs\Python\Python37\lib\ssl.py", line 849, in read
    return self._sslobj.read(len, buffer)
  File "C:\Users\Kryukov_MM\AppData\Local\Programs\Python\Python37\lib\ssl.py", line 615, in read
    v = self._sslobj.read(len, buffer)
socket.timeout: The read operation timed out

During handling of the above exception, another exception occurred:

Traceback (most recent call last):
  File "C:\Users\Kryukov_MM\AppData\Local\Programs\Python\Python37\lib\site-packages\telegram\utils\request.py", line 190, in _request_wrapper
    resp = self._con_pool.request(*args, **kwargs)
  File "C:\Users\Kryukov_MM\AppData\Local\Programs\Python\Python37\lib\site-packages\telegram\vendor\ptb_urllib3\urllib3\request.py", line 70, in request
    **urlopen_kw)
  File "C:\Users\Kryukov_MM\AppData\Local\Programs\Python\Python37\lib\site-packages\telegram\vendor\ptb_urllib3\urllib3\request.py", line 148, in request_encode_body
    return self.urlopen(method, url, **extra_kw)
  File "C:\Users\Kryukov_MM\AppData\Local\Programs\Python\Python37\lib\site-packages\telegram\vendor\ptb_urllib3\urllib3\poolmanager.py", line 244, in urlopen
    response = conn.urlopen(method, u.request_uri, **kw)
  File "C:\Users\Kryukov_MM\AppData\Local\Programs\Python\Python37\lib\site-packages\telegram\vendor\ptb_urllib3\urllib3\connectionpool.py", line 666, in urlopen
    _stacktrace=sys.exc_info()[2])
  File "C:\Users\Kryukov_MM\AppData\Local\Programs\Python\Python37\lib\site-packages\telegram\vendor\ptb_urllib3\urllib3\util\retry.py", line 347, in increment
    raise six.reraise(type(error), error, _stacktrace)
  File "C:\Users\Kryukov_MM\AppData\Local\Programs\Python\Python37\lib\site-packages\telegram\vendor\ptb_urllib3\urllib3\packages\six.py", line 686, in reraise
    raise value
  File "C:\Users\Kryukov_MM\AppData\Local\Programs\Python\Python37\lib\site-packages\telegram\vendor\ptb_urllib3\urllib3\connectionpool.py", line 617, in urlopen
    chunked=chunked)
  File "C:\Users\Kryukov_MM\AppData\Local\Programs\Python\Python37\lib\site-packages\telegram\vendor\ptb_urllib3\urllib3\connectionpool.py", line 405, in _make_request
    exc_cls=ReadTimeoutError)
  File "C:\Users\Kryukov_MM\AppData\Local\Programs\Python\Python37\lib\site-packages\telegram\vendor\ptb_urllib3\urllib3\connectionpool.py", line 321, in _raise_timeout
    raise exc_cls(*args)
telegram.vendor.ptb_urllib3.urllib3.exceptions.ReadTimeoutError: HTTPSConnectionPool(host='api.telegram.org', port=443): Read timed out. (read timeout=12.0)

During handling of the above exception, another exception occurred:

Traceback (most recent call last):
  File "C:\Users\Kryukov_MM\AppData\Local\Programs\Python\Python37\lib\site-packages\telegram\ext\updater.py", line 286, in _start_polling
    allowed_updates=allowed_updates)
  File "C:\Users\Kryukov_MM\AppData\Local\Programs\Python\Python37\lib\site-packages\telegram\bot.py", line 60, in decorator
    result = func(self, *args, **kwargs)
  File "C:\Users\Kryukov_MM\AppData\Local\Programs\Python\Python37\lib\site-packages\telegram\bot.py", line 1720, in get_updates
    result = self._request.post(url, data, timeout=float(read_latency) + float(timeout))
  File "C:\Users\Kryukov_MM\AppData\Local\Programs\Python\Python37\lib\site-packages\telegram\utils\request.py", line 272, in post
    **urlopen_kwargs)
  File "C:\Users\Kryukov_MM\AppData\Local\Programs\Python\Python37\lib\site-packages\telegram\utils\request.py", line 192, in _request_wrapper
    raise TimedOut()
telegram.error.TimedOut: Timed out
telegram.ext.updater - ERROR - Error while getting Updates: Timed out
telegram.ext.dispatcher - ERROR - No error handlers are registered, logging exception...
Traceback (most recent call last):
  File "C:\Users\Kryukov_MM\AppData\Local\Programs\Python\Python37\lib\site-packages\telegram\vendor\ptb_urllib3\urllib3\connectionpool.py", line 402, in _make_request
    six.raise_from(e, None)
  File "<string>", line 2, in raise_from
  File "C:\Users\Kryukov_MM\AppData\Local\Programs\Python\Python37\lib\site-packages\telegram\vendor\ptb_urllib3\urllib3\connectionpool.py", line 398, in _make_request
    httplib_response = conn.getresponse()
  File "C:\Users\Kryukov_MM\AppData\Local\Programs\Python\Python37\lib\http\client.py", line 1321, in getresponse
    response.begin()
  File "C:\Users\Kryukov_MM\AppData\Local\Programs\Python\Python37\lib\http\client.py", line 296, in begin
    version, status, reason = self._read_status()
  File "C:\Users\Kryukov_MM\AppData\Local\Programs\Python\Python37\lib\http\client.py", line 257, in _read_status
    line = str(self.fp.readline(_MAXLINE + 1), "iso-8859-1")
  File "C:\Users\Kryukov_MM\AppData\Local\Programs\Python\Python37\lib\socket.py", line 589, in readinto
    return self._sock.recv_into(b)
  File "C:\Users\Kryukov_MM\AppData\Local\Programs\Python\Python37\lib\ssl.py", line 987, in recv_into
    return self.read(nbytes, buffer)
  File "C:\Users\Kryukov_MM\AppData\Local\Programs\Python\Python37\lib\ssl.py", line 849, in read
    return self._sslobj.read(len, buffer)
  File "C:\Users\Kryukov_MM\AppData\Local\Programs\Python\Python37\lib\ssl.py", line 615, in read
    v = self._sslobj.read(len, buffer)
socket.timeout: The read operation timed out

During handling of the above exception, another exception occurred:

Traceback (most recent call last):
  File "C:\Users\Kryukov_MM\AppData\Local\Programs\Python\Python37\lib\site-packages\telegram\utils\request.py", line 190, in _request_wrapper
    resp = self._con_pool.request(*args, **kwargs)
  File "C:\Users\Kryukov_MM\AppData\Local\Programs\Python\Python37\lib\site-packages\telegram\vendor\ptb_urllib3\urllib3\request.py", line 70, in request
    **urlopen_kw)
  File "C:\Users\Kryukov_MM\AppData\Local\Programs\Python\Python37\lib\site-packages\telegram\vendor\ptb_urllib3\urllib3\request.py", line 148, in request_encode_body
    return self.urlopen(method, url, **extra_kw)
  File "C:\Users\Kryukov_MM\AppData\Local\Programs\Python\Python37\lib\site-packages\telegram\vendor\ptb_urllib3\urllib3\poolmanager.py", line 244, in urlopen
    response = conn.urlopen(method, u.request_uri, **kw)
  File "C:\Users\Kryukov_MM\AppData\Local\Programs\Python\Python37\lib\site-packages\telegram\vendor\ptb_urllib3\urllib3\connectionpool.py", line 666, in urlopen
    _stacktrace=sys.exc_info()[2])
  File "C:\Users\Kryukov_MM\AppData\Local\Programs\Python\Python37\lib\site-packages\telegram\vendor\ptb_urllib3\urllib3\util\retry.py", line 347, in increment
    raise six.reraise(type(error), error, _stacktrace)
  File "C:\Users\Kryukov_MM\AppData\Local\Programs\Python\Python37\lib\site-packages\telegram\vendor\ptb_urllib3\urllib3\packages\six.py", line 686, in reraise
    raise value
  File "C:\Users\Kryukov_MM\AppData\Local\Programs\Python\Python37\lib\site-packages\telegram\vendor\ptb_urllib3\urllib3\connectionpool.py", line 617, in urlopen
    chunked=chunked)
  File "C:\Users\Kryukov_MM\AppData\Local\Programs\Python\Python37\lib\site-packages\telegram\vendor\ptb_urllib3\urllib3\connectionpool.py", line 405, in _make_request
    exc_cls=ReadTimeoutError)
  File "C:\Users\Kryukov_MM\AppData\Local\Programs\Python\Python37\lib\site-packages\telegram\vendor\ptb_urllib3\urllib3\connectionpool.py", line 321, in _raise_timeout
    raise exc_cls(*args)
telegram.vendor.ptb_urllib3.urllib3.exceptions.ReadTimeoutError: HTTPSConnectionPool(host='api.telegram.org', port=443): Read timed out. (read timeout=12.0)

During handling of the above exception, another exception occurred:

Traceback (most recent call last):
  File "C:\Users\Kryukov_MM\AppData\Local\Programs\Python\Python37\lib\site-packages\telegram\ext\updater.py", line 286, in _start_polling
    allowed_updates=allowed_updates)
  File "C:\Users\Kryukov_MM\AppData\Local\Programs\Python\Python37\lib\site-packages\telegram\bot.py", line 60, in decorator
    result = func(self, *args, **kwargs)
  File "C:\Users\Kryukov_MM\AppData\Local\Programs\Python\Python37\lib\site-packages\telegram\bot.py", line 1720, in get_updates
    result = self._request.post(url, data, timeout=float(read_latency) + float(timeout))
  File "C:\Users\Kryukov_MM\AppData\Local\Programs\Python\Python37\lib\site-packages\telegram\utils\request.py", line 272, in post
    **urlopen_kwargs)
  File "C:\Users\Kryukov_MM\AppData\Local\Programs\Python\Python37\lib\site-packages\telegram\utils\request.py", line 192, in _request_wrapper
    raise TimedOut()
telegram.error.TimedOut: Timed out
telegram.ext.updater - ERROR - Error while getting Updates: Timed out
telegram.ext.dispatcher - ERROR - No error handlers are registered, logging exception...
Traceback (most recent call last):
  File "C:\Users\Kryukov_MM\AppData\Local\Programs\Python\Python37\lib\site-packages\telegram\vendor\ptb_urllib3\urllib3\connectionpool.py", line 402, in _make_request
    six.raise_from(e, None)
  File "<string>", line 2, in raise_from
  File "C:\Users\Kryukov_MM\AppData\Local\Programs\Python\Python37\lib\site-packages\telegram\vendor\ptb_urllib3\urllib3\connectionpool.py", line 398, in _make_request
    httplib_response = conn.getresponse()
  File "C:\Users\Kryukov_MM\AppData\Local\Programs\Python\Python37\lib\http\client.py", line 1321, in getresponse
    response.begin()
  File "C:\Users\Kryukov_MM\AppData\Local\Programs\Python\Python37\lib\http\client.py", line 296, in begin
    version, status, reason = self._read_status()
  File "C:\Users\Kryukov_MM\AppData\Local\Programs\Python\Python37\lib\http\client.py", line 257, in _read_status
    line = str(self.fp.readline(_MAXLINE + 1), "iso-8859-1")
  File "C:\Users\Kryukov_MM\AppData\Local\Programs\Python\Python37\lib\socket.py", line 589, in readinto
    return self._sock.recv_into(b)
  File "C:\Users\Kryukov_MM\AppData\Local\Programs\Python\Python37\lib\ssl.py", line 987, in recv_into
    return self.read(nbytes, buffer)
  File "C:\Users\Kryukov_MM\AppData\Local\Programs\Python\Python37\lib\ssl.py", line 849, in read
    return self._sslobj.read(len, buffer)
  File "C:\Users\Kryukov_MM\AppData\Local\Programs\Python\Python37\lib\ssl.py", line 615, in read
    v = self._sslobj.read(len, buffer)
socket.timeout: The read operation timed out

During handling of the above exception, another exception occurred:

Traceback (most recent call last):
  File "C:\Users\Kryukov_MM\AppData\Local\Programs\Python\Python37\lib\site-packages\telegram\utils\request.py", line 190, in _request_wrapper
    resp = self._con_pool.request(*args, **kwargs)
  File "C:\Users\Kryukov_MM\AppData\Local\Programs\Python\Python37\lib\site-packages\telegram\vendor\ptb_urllib3\urllib3\request.py", line 70, in request
    **urlopen_kw)
  File "C:\Users\Kryukov_MM\AppData\Local\Programs\Python\Python37\lib\site-packages\telegram\vendor\ptb_urllib3\urllib3\request.py", line 148, in request_encode_body
    return self.urlopen(method, url, **extra_kw)
  File "C:\Users\Kryukov_MM\AppData\Local\Programs\Python\Python37\lib\site-packages\telegram\vendor\ptb_urllib3\urllib3\poolmanager.py", line 244, in urlopen
    response = conn.urlopen(method, u.request_uri, **kw)
  File "C:\Users\Kryukov_MM\AppData\Local\Programs\Python\Python37\lib\site-packages\telegram\vendor\ptb_urllib3\urllib3\connectionpool.py", line 666, in urlopen
    _stacktrace=sys.exc_info()[2])
  File "C:\Users\Kryukov_MM\AppData\Local\Programs\Python\Python37\lib\site-packages\telegram\vendor\ptb_urllib3\urllib3\util\retry.py", line 347, in increment
    raise six.reraise(type(error), error, _stacktrace)
  File "C:\Users\Kryukov_MM\AppData\Local\Programs\Python\Python37\lib\site-packages\telegram\vendor\ptb_urllib3\urllib3\packages\six.py", line 686, in reraise
    raise value
  File "C:\Users\Kryukov_MM\AppData\Local\Programs\Python\Python37\lib\site-packages\telegram\vendor\ptb_urllib3\urllib3\connectionpool.py", line 617, in urlopen
    chunked=chunked)
  File "C:\Users\Kryukov_MM\AppData\Local\Programs\Python\Python37\lib\site-packages\telegram\vendor\ptb_urllib3\urllib3\connectionpool.py", line 405, in _make_request
    exc_cls=ReadTimeoutError)
  File "C:\Users\Kryukov_MM\AppData\Local\Programs\Python\Python37\lib\site-packages\telegram\vendor\ptb_urllib3\urllib3\connectionpool.py", line 321, in _raise_timeout
    raise exc_cls(*args)
telegram.vendor.ptb_urllib3.urllib3.exceptions.ReadTimeoutError: HTTPSConnectionPool(host='api.telegram.org', port=443): Read timed out. (read timeout=12.0)

During handling of the above exception, another exception occurred:

Traceback (most recent call last):
  File "C:\Users\Kryukov_MM\AppData\Local\Programs\Python\Python37\lib\site-packages\telegram\ext\updater.py", line 286, in _start_polling
    allowed_updates=allowed_updates)
  File "C:\Users\Kryukov_MM\AppData\Local\Programs\Python\Python37\lib\site-packages\telegram\bot.py", line 60, in decorator
    result = func(self, *args, **kwargs)
  File "C:\Users\Kryukov_MM\AppData\Local\Programs\Python\Python37\lib\site-packages\telegram\bot.py", line 1720, in get_updates
    result = self._request.post(url, data, timeout=float(read_latency) + float(timeout))
  File "C:\Users\Kryukov_MM\AppData\Local\Programs\Python\Python37\lib\site-packages\telegram\utils\request.py", line 272, in post
    **urlopen_kwargs)
  File "C:\Users\Kryukov_MM\AppData\Local\Programs\Python\Python37\lib\site-packages\telegram\utils\request.py", line 192, in _request_wrapper
    raise TimedOut()
telegram.error.TimedOut: Timed out
telegram.ext.updater - ERROR - Error while getting Updates: Timed out
telegram.ext.dispatcher - ERROR - No error handlers are registered, logging exception...
Traceback (most recent call last):
  File "C:\Users\Kryukov_MM\AppData\Local\Programs\Python\Python37\lib\site-packages\telegram\vendor\ptb_urllib3\urllib3\connectionpool.py", line 402, in _make_request
    six.raise_from(e, None)
  File "<string>", line 2, in raise_from
  File "C:\Users\Kryukov_MM\AppData\Local\Programs\Python\Python37\lib\site-packages\telegram\vendor\ptb_urllib3\urllib3\connectionpool.py", line 398, in _make_request
    httplib_response = conn.getresponse()
  File "C:\Users\Kryukov_MM\AppData\Local\Programs\Python\Python37\lib\http\client.py", line 1321, in getresponse
    response.begin()
  File "C:\Users\Kryukov_MM\AppData\Local\Programs\Python\Python37\lib\http\client.py", line 296, in begin
    version, status, reason = self._read_status()
  File "C:\Users\Kryukov_MM\AppData\Local\Programs\Python\Python37\lib\http\client.py", line 257, in _read_status
    line = str(self.fp.readline(_MAXLINE + 1), "iso-8859-1")
  File "C:\Users\Kryukov_MM\AppData\Local\Programs\Python\Python37\lib\socket.py", line 589, in readinto
    return self._sock.recv_into(b)
  File "C:\Users\Kryukov_MM\AppData\Local\Programs\Python\Python37\lib\ssl.py", line 987, in recv_into
    return self.read(nbytes, buffer)
  File "C:\Users\Kryukov_MM\AppData\Local\Programs\Python\Python37\lib\ssl.py", line 849, in read
    return self._sslobj.read(len, buffer)
  File "C:\Users\Kryukov_MM\AppData\Local\Programs\Python\Python37\lib\ssl.py", line 615, in read
    v = self._sslobj.read(len, buffer)
socket.timeout: The read operation timed out

During handling of the above exception, another exception occurred:

Traceback (most recent call last):
  File "C:\Users\Kryukov_MM\AppData\Local\Programs\Python\Python37\lib\site-packages\telegram\utils\request.py", line 190, in _request_wrapper
    resp = self._con_pool.request(*args, **kwargs)
  File "C:\Users\Kryukov_MM\AppData\Local\Programs\Python\Python37\lib\site-packages\telegram\vendor\ptb_urllib3\urllib3\request.py", line 70, in request
    **urlopen_kw)
  File "C:\Users\Kryukov_MM\AppData\Local\Programs\Python\Python37\lib\site-packages\telegram\vendor\ptb_urllib3\urllib3\request.py", line 148, in request_encode_body
    return self.urlopen(method, url, **extra_kw)
  File "C:\Users\Kryukov_MM\AppData\Local\Programs\Python\Python37\lib\site-packages\telegram\vendor\ptb_urllib3\urllib3\poolmanager.py", line 244, in urlopen
    response = conn.urlopen(method, u.request_uri, **kw)
  File "C:\Users\Kryukov_MM\AppData\Local\Programs\Python\Python37\lib\site-packages\telegram\vendor\ptb_urllib3\urllib3\connectionpool.py", line 666, in urlopen
    _stacktrace=sys.exc_info()[2])
  File "C:\Users\Kryukov_MM\AppData\Local\Programs\Python\Python37\lib\site-packages\telegram\vendor\ptb_urllib3\urllib3\util\retry.py", line 347, in increment
    raise six.reraise(type(error), error, _stacktrace)
  File "C:\Users\Kryukov_MM\AppData\Local\Programs\Python\Python37\lib\site-packages\telegram\vendor\ptb_urllib3\urllib3\packages\six.py", line 686, in reraise
    raise value
  File "C:\Users\Kryukov_MM\AppData\Local\Programs\Python\Python37\lib\site-packages\telegram\vendor\ptb_urllib3\urllib3\connectionpool.py", line 617, in urlopen
    chunked=chunked)
  File "C:\Users\Kryukov_MM\AppData\Local\Programs\Python\Python37\lib\site-packages\telegram\vendor\ptb_urllib3\urllib3\connectionpool.py", line 405, in _make_request
    exc_cls=ReadTimeoutError)
  File "C:\Users\Kryukov_MM\AppData\Local\Programs\Python\Python37\lib\site-packages\telegram\vendor\ptb_urllib3\urllib3\connectionpool.py", line 321, in _raise_timeout
    raise exc_cls(*args)
telegram.vendor.ptb_urllib3.urllib3.exceptions.ReadTimeoutError: HTTPSConnectionPool(host='api.telegram.org', port=443): Read timed out. (read timeout=12.0)

During handling of the above exception, another exception occurred:

Traceback (most recent call last):
  File "C:\Users\Kryukov_MM\AppData\Local\Programs\Python\Python37\lib\site-packages\telegram\ext\updater.py", line 286, in _start_polling
    allowed_updates=allowed_updates)
  File "C:\Users\Kryukov_MM\AppData\Local\Programs\Python\Python37\lib\site-packages\telegram\bot.py", line 60, in decorator
    result = func(self, *args, **kwargs)
  File "C:\Users\Kryukov_MM\AppData\Local\Programs\Python\Python37\lib\site-packages\telegram\bot.py", line 1720, in get_updates
    result = self._request.post(url, data, timeout=float(read_latency) + float(timeout))
  File "C:\Users\Kryukov_MM\AppData\Local\Programs\Python\Python37\lib\site-packages\telegram\utils\request.py", line 272, in post
    **urlopen_kwargs)
  File "C:\Users\Kryukov_MM\AppData\Local\Programs\Python\Python37\lib\site-packages\telegram\utils\request.py", line 192, in _request_wrapper
    raise TimedOut()
telegram.error.TimedOut: Timed out
telegram.ext.updater - WARNING - Exiting immediately!
